<robot name="my_robot">
  <!-- Base Link -->
  <link name="base_link">
    <visual>
      <geometry>
        <box size="0.5 0.4 0.2"/>
      </geometry>
    </visual>
    <collision>
      <geometry>
        <box size="0.5 0.4 0.2"/>
      </geometry>
    </collision>
    <inertial>
      <mass value="1.0"/>
    </inertial>
  </link>

  <!-- Left Wheel -->
  <link name="left_wheel"/>
  <joint name="left_wheel_joint" type="continuous">
    <parent link="base_link"/>
    <child link="left_wheel"/>
    <origin xyz="0.2 0.1 0"/>
    <axis xyz="0 1 0"/>
  </joint>

  <!-- Right Wheel -->
  <link name="right_wheel"/>
  <joint name="right_wheel_joint" type="continuous">
    <parent link="base_link"/>
    <child link="right_wheel"/>
    <origin xyz="0.2 -0.1 0"/>
    <axis xyz="0 1 0"/>
  </joint>

  <!-- Differential Drive Plugin -->
  <gazebo>
    <plugin name="gazebo_ros_diff_drive" filename="libgazebo_ros_diff_drive.so">
      <ros>
        <remapping>cmd_vel:=/cmd_vel</remapping>
      </ros>
      <leftJoint>left_wheel_joint</leftJoint>
      <rightJoint>right_wheel_joint</rightJoint>
      <wheelSeparation>0.2</wheelSeparation>
      <wheelDiameter>0.15</wheelDiameter>
      <maxTorque>10.0</maxTorque>
    </plugin>
  </gazebo>
</robot>
